Workbook

Sheet CONFIG
A1: UNIDAD | B1: N DE NIÑOS
A2: CASTORES
A3: LOBATOS
A4: EXPLORADORES
A5: PIONEROS
A6: RUTAS PANDORA
A7: RUTAS ICARO
A9: INSTRUCCIONES: | B9: Rellena la columna B con el número de niños de cada unidad para actualizar las cantidades dinámicas.

Sheet LISTA DE LA COMPRA
A1: MATERIAL | B1: CATEGORÍA | C1: TOTAL | D1: CASTORES | E1: LOBATOS | F1: EXPLORADORES (TROPA) | G1: PIONEROS | H1: RUTAS | I1: TIPO | J1: DETALLE (texto literal por actividad) | K1: CAJA | L1: COMPRADO ✓
A2: (De la descripción) Garbanzos dorados (rupias) | B2: Otros | C2: =SUM(D2:H2) | D2: 0 | E2: 1 | F2: 0 | G2: 0 | H2: 0 | I2: YA HAY (bases) - revisar | J2: LOBATOS - GRUPAL: Barracas - El Gran Bazar (D-26/07 tarde): «(De la descripción) Garbanzos dorados (rupias)»
A3: (Lo trae el niño) Botella de agua | B3: Otros | C3: =SUM(D3:H3) | D3: 0 | E3: 1 | F3: 0 | G3: 0 | H3: 0 | I3: YA HAY (bases) - revisar | J3: LOBATOS - Voluntariado conjunto Lobatos-Pioneros (J-23/07 mañana): «(Lo trae el niño) Botella de agua»
A4: (Se encarga la unidad) Cuadrilátero | B4: Otros | C4: =SUM(D4:H4) | D4: 0 | E4: 0 | F4: 1 | G4: 0 | H4: 0 | I4: YA HAY (bases) - revisar | J4: EXPLORADORES - FELSA (V-24/07 tarde 1): «(Se encarga la unidad) Cuadrilátero»
A5: (Se encarga la unidad) Cuadrilátero acabado | B5: Otros | C5: =SUM(D5:H5) | D5: 0 | E5: 0 | F5: 1 | G5: 0 | H5: 0 | I5: YA HAY (bases) - revisar | J5: EXPLORADORES - Inauguración de la FELSA (V-17/07 tarde 2): «(Se encarga la unidad) Cuadrilátero acabado»
A6: (Sin material listado) | B6: Otros | C6: =SUM(D6:H6) | D6: 0 | E6: 0 | F6: 0 | G6: 0 | H6: 1 | I6: YA HAY (bases) - revisar | J6: RUTAS ICARO - Stalking con Pandora y pipis (D-26/07 noche): «(Sin material listado)»
A7: 1 bote de espárragos | B7: Otros | C7: =SUM(D7:H7) | D7: 0 | E7: 0 | F7: 1 | G7: 0 | H7: 0 | I7: YA HAY (bases) - revisar | J7: EXPLORADORES - Velada de terror (X-22/07 noche): «1 bote de espárragos»
A8: 1 caja | B8: Otros | C8: =SUM(D8:H8) | D8: 0 | E8: 0 | F8: 1 | G8: 0 | H8: 0 | I8: YA HAY (bases) - revisar | J8: EXPLORADORES - Velada de terror (X-22/07 noche): «1 caja»
A9: 1 llave | B9: Otros | C9: =SUM(D9:H9) | D9: 0 | E9: 0 | F9: 1 | G9: 0 | H9: 0 | I9: YA HAY (bases) - revisar | J9: EXPLORADORES - Velada de terror (X-22/07 noche): «1 llave»
A10: 1 paquete de chía | B10: Otros | C10: =SUM(D10:H10) | D10: 0 | E10: 0 | F10: 1 | G10: 0 | H10: 0 | I10: YA HAY (bases) - revisar | J10: EXPLORADORES - Velada de terror (X-22/07 noche): «1 paquete de chía»
A11: 10 mantas | B11: Otros | C11: =SUM(D11:H11) | D11: 0 | E11: 0 | F11: 10 | G11: 0 | H11: 0 | I11: YA HAY (bases) - revisar | J11: EXPLORADORES - Velada de terror (X-22/07 noche): «10 mantas»
A12: 150 globos | B12: Otros | C12: =SUM(D12:H12) | D12: 150 | E12: 0 | F12: 0 | G12: 0 | H12: 0 | I12: YA HAY (bases) - revisar | J12: CASTORES - T.E.G.A. (Torneo de Globos) (V-17/07 tarde 2): «150 globos»
A13: 2 barreños | B13: Otros | C13: =SUM(D13:H13) | D13: 2 | E13: 0 | F13: 0 | G13: 0 | H13: 0 | I13: YA HAY (bases) - revisar | J13: CASTORES - Actividad de agua: El descenso del Ganges (V-24/07 mañana): «2 barreños»
... A40: Anillas de llavero | B40: Papeleria/manualidades | C40: =SUM(D40:H40) | D40: 0 | E40: 0 | F40: 0 | G40: 0 | H40: 1 | I40: COMPRAR | J40: RUTAS PANDORA - Miss y Mister (llaveros) (X-29/07 tarde): «Anillas de llavero»
A41: Arcilla | B41: Papeleria/manualidades | C41: =SUM(D41:H41) | D41: =CONFIG!$B$2*0.5 | E41: 0 | F41: 0 | G41: 0 | H41: 0 | I41: COMPRAR | J41: CASTORES - Taller de arcilla (S-25/07 tarde 1): «X kilos de arcilla (AÑADIR CUANDO SE SEPA Nº DE NIÑOS)»
A42: Arco | B42: Otros | C42: =SUM(D42:H42) | D42: 1 | E42: 1 | F42: 0 | G42: 0 | H42: 0 | I42: YA HAY (bases) - revisar | J42: CASTORES - Gran Juego: El Taj perdido (con Lobatos) (S-18/07 tarde 1): «Arco» LOBATOS - El Taj perdido (con Castores) (S-18/07 tarde 1): «Arco»
A43: Arena fina | B43: Otros | C43: =SUM(D43:H43) | D43: 0 | E43: 1 | F43: 0 | G43: 0 | H43: 1 | I43: YA HAY (bases) - revisar | J43: LOBATOS - Clan Ícaro: brújula casera y potabilizar (V-24/07 tarde 1): «Arena fina» RUTAS ICARO - Técnicas scouts (brújula casera, potabilizar) (V-24/07): «Arena fina»
A44: Arena gruesa | B44: Otros | C44: =SUM(D44:H44) | D44: 0 | E44: 1 | F44: 0 | G44: 0 | H44: 1 | I44: YA HAY (bases) - revisar | J44: LOBATOS - Clan Ícaro: brújula casera y potabilizar (V-24/07 tarde 1): «Arena gruesa» RUTAS ICARO - Técnicas scouts (brújula casera, potabilizar) (V-24/07): «Arena gruesa»
A45: Aros de plástico | B45: Juegos/deporte | C45: =SUM(D45:H45) | D45: 0 | E45: 3 | F45: 0 | G45: 0 | H45: 2 | I45: YA HAY (bases) - revisar | J45: LOBATOS - De aventura en la India (V-17/07 tarde 2): «Aros» LOBATOS - Actividad lobatos (Clan Ícaro - Charlie y David) (J-23/07 tarde 2): «Un palo/algo para meter aros» LOBATOS - Actividad lobatos (Clan Ícaro - Charlie y David) (J-23/07 tarde 2): «Aros» RUTAS ICARO - Actividad para Lobatos (Charlie y David) (J-23/07): «Un palo para meter aros» RUTAS ICARO - Actividad para Lobatos (Charlie y David) (J-23/07): «Aros»
A46: Awen (peluche castor) | B46: Otros | C46: =SUM(D46:H46) | D46: 1 | E46: 0 | F46: 0 | G46: 0 | H46: 0 | I46: YA HAY (bases) - revisar | J46: CASTORES - Consejo de troncos (V-24/07 noche): «Awen (peluche castor)»
A47: Balde | B47: Otros | C47: =SUM(D47:H47) | D47: 1 | E47: 1 | F47: 0 | G47: 1 | H47: 2 | I47: YA HAY (bases) - revisar | J47: CASTORES - Gran Juego: El Taj perdido (con Lobatos) (S-18/07 tarde 1): «Balde» LOBATOS - El Taj perdido (con Castores) (S-18/07 tarde 1): «Balde» PIONEROS - Actividad Clan Ícaro - Drogas (S-18/07 tarde 1): «Balde» RUTAS PANDORA - Actividad de adicciones con pipis (J-16/07): «Balde» RUTAS ICARO - Taller para Pioneros - Drogas (S-18/07): «Balde»
A48: Balde de agua | B48: Otros | C48: =SUM(D48:H48) | D48: 0 | E48: 1 | F48: 0 | G48: 0 | H48: 0 | I48: YA HAY (bases) - revisar | J48: LOBATOS - GRUPAL: Barracas - El Gran Bazar (D-26/07 tarde): «Balde de agua»
A49: Balones y pelotas deportivas / Petanca | B49: Juegos/deporte | C49: =SUM(D49:H49) | D49: 1 | E49: 8 | F49: 3 | G49: 4 | H49: 7 | I49: YA HAY (bases) - revisar | J49: CASTORES - Normas de campamento + juegos (J-16/07 tarde 2): «Balón» LOBATOS - Juegos (J-16/07 tarde 2): «Balón goma espuma» LOBATOS - Juegos India (V-17/07 mañana): «Pelota de tenis» LOBATOS - De aventura en la India (V-17/07 tarde 2): «Pelota blanda» LOBATOS - El amuleto del elefante sagrado (orientación) (X-22/07 tarde): «Balón blando» LOBATOS - Actividad lobatos (Clan Ícaro - Charlie y David) (J-23/07 tarde 2): «Set de petanca» LOBATOS - Gymkana de agua (V-24/07 mañana): «Pelotas de pin pon 10» LOBATOS - Lobatolimpiadas (S-25/07 tarde 2): «Pelota volley» LOBATOS - GRUPAL: Barracas - El Gran Bazar (D-26/07 tarde): «Pelotas de ping pong» EXPLORADORES - Actividad Clan Ícaro (Trivial) (X-22/07 tarde 1): «Balón» EXPLORADORES - Actividad Clan Ícaro (Trivial) (X-22/07 tarde 1): «Pelotas de pin pon» EXPLORADORES - Jugger (X-22/07 tarde 2): «Pelota jugger» PIONEROS - Gymkhana deportes (V-17/07 tarde): «Palas de playa y pelota» PIONEROS - Gymkhana deportes (V-17/07 tarde): «Petanca» PIONEROS - Juegos de agua (J-23/07 tarde 1): «Balones blanditos para agua» PIONEROS - Velada NNEE (S-25/07 noche): «Petanca» RUTAS ICARO - Actividad moverse (Charlie) (S-18/07): «Pelotas» RUTAS ICARO - Actividad para Tropa: Trivial (X-22/07): «Balón» RUTAS ICARO - Actividad para Tropa: Trivial (X-22/07): «Pelotas de pin pon» RUTAS ICARO - Actividad para Lobatos (Charlie y David) (J-23/07): «Set de petanca» RUTAS ICARO - Jugger con Pandora (S-25/07): «Balón de rugby» RUTAS ICARO - OLIMPIADAS (grupal) (X-29/07 mañana): «Balón» RUTAS ICARO - OLIMPIADAS (grupal) (X-29/07 mañana): «Pelotas de pin-pon»
A50: Bancos | B50: Otros | C50: =SUM(D50:H50) | D50: 0 | E50: 1 | F50: 0 | G50: 0 | H50: 0 | I50: YA HAY (bases) - revisar | J50: LOBATOS - De aventura en la India (V-17/07 tarde 2): «Bancos»
A51: Bancos del comedor | B51: Otros | C51: =SUM(D51:H51) | D51: 0 | E51: 0 | F51: 0 | G51: 0 | H51: 1 | I51: YA HAY (bases) - revisar | J51: RUTAS ICARO - OLIMPIADAS (grupal) (X-29/07 mañana): «Bancos del comedor»
A52: Bancos, mesa (circuito) | B52: Otros | C52: =SUM(D52:H52) | D52: 0 | E52: 0 | F52: 0 | G52: 1 | H52: 0 | I52: YA HAY (bases) - revisar | J52: PIONEROS - Gymkhana deportes (V-17/07 tarde): «Bancos, mesa (circuito)»
A53: Bandera de castores | B53: Otros | C53: =SUM(D53:H53) | D53: 2 | E53: 0 | F53: 0 | G53: 0 | H53: 0 | I53: YA HAY (bases) - revisar | J53: CASTORES - Montaje de tiendas (J-16/07 mañana): «Bandera de castores» CASTORES - Construcciones zona común (V-17/07 mañana): «Bandera de castores»
... A75: Cartulina para el himno | B75: Papeleria/manualidades | C75: =SUM(D75:H75) | D75: 0 | E75: 1 | F75: 0 | G75: 0 | H75: 0 | I75: COMPRAR | J75: LOBATOS - ILLRA (L-20/07 tarde): «Cartulina para el himno»
A76: Cartulinas A4 de colores | B76: Papeleria/manualidades | C76: =SUM(D76:H76) | D76: 2 | E76: =CONFIG!$B$3 | F76: 0 | G76: 0 | H76: 1 | I76: COMPRAR | J76: CASTORES - Actividad Clan Ícaro (X-22/07 tarde 2): «Cartulina» CASTORES - Talleres pinza (Bolsa de juegos): «Cartulina» LOBATOS - Territorios (V-17/07 tarde 1): «Cartulinas A4» RUTAS ICARO - Actividad para Castores (X-22/07): «Cartulina»
A77: Cartulinas amarillas 2 A4 | B77: Papeleria/manualidades | C77: =SUM(D77:H77) | D77: 0 | E77: 0 | F77: 0 | G77: 1 | H77: 0 | I77: COMPRAR | J77: PIONEROS - Taller de estrellas (V-17/07 noche): «Cartulinas amarillas 2 A4»
A78: Cartulinas de colores A4 (1 por niño) | B78: Papeleria/manualidades | C78: =SUM(D78:H78) | D78: 1 | E78: 0 | F78: 0 | G78: 0 | H78: 0 | I78: COMPRAR | J78: CASTORES - Taller de sobres y cartas (Bolsa de juegos): «Cartulinas de colores A4 (1 por niño)»
A79: Cartulinas negras | B79: Papeleria/manualidades | C79: =SUM(D79:H79) | D79: 0 | E79: 20 | F79: 0 | G79: 0 | H79: 0 | I79: COMPRAR | J79: LOBATOS - Taller de estrellas (X-22/07 noche): «20 cartulinas negras»
A80: Cascos inalámbricos y un móvil (o tapones) | B80: Otros | C80: =SUM(D80:H80) | D80: 0 | E80: 0 | F80: 0 | G80: 0 | H80: 1 | I80: YA HAY (bases) - revisar | J80: RUTAS PANDORA - Cocina con hándicaps (gyozas/empanadillas) (J-23/07): «Cascos inalámbricos y un móvil (o tapones)»
A81: Casquería (texturas, en descripción) | B81: Otros | C81: =SUM(D81:H81) | D81: 1 | E81: 0 | F81: 0 | G81: 0 | H81: 0 | I81: YA HAY (bases) - revisar | J81: CASTORES - Entrenamiento Caza Gamusino (M-21/07 tarde 1): «Casquería (texturas, en descripción)»
A82: Celo | B82: Papeleria/manualidades | C82: =SUM(D82:H82) | D82: 2 | E82: 1 | F82: 0 | G82: 1 | H82: 0 | I82: COMPRAR | J82: CASTORES - Normas de campamento + juegos (J-16/07 tarde 2): «Celo gordo» CASTORES - T.E.G.A. (Torneo de Globos) (V-17/07 tarde 2): «Celo» LOBATOS - Taller de pulseras (D-19/07 tarde): «Celo» PIONEROS - Pulseras (Lluvia): «Celo»
A83: Cerillas o mechero | B83: Otros | C83: =SUM(D83:H83) | D83: 0 | E83: 0 | F83: 0 | G83: 0 | H83: 1 | I83: YA HAY (bases) - revisar | J83: RUTAS PANDORA - Acampada volante (x3 días) (D-19 a M-21/07): «Cerillas o mechero»
A84: Cerillas/mecheros | B84: Otros | C84: =SUM(D84:H84) | D84: 0 | E84: 0 | F84: 0 | G84: 0 | H84: 1 | I84: YA HAY (bases) - revisar | J84: RUTAS PANDORA - Línea de la vida (Volante noche): «Cerillas/mecheros»
A85: Chalecos | B85: Otros | C85: =SUM(D85:H85) | D85: 0 | E85: 0 | F85: 1 | G85: 1 | H85: 5 | I85: YA HAY (bases) - revisar | J85: EXPLORADORES - Volante (x3 días) (D-19 a M-21/07): «Chalecos» PIONEROS - Volantes (x3 días) (D-19 a M-21/07): «Chalecos» RUTAS PANDORA - Acampada volante (x3 días) (D-19 a M-21/07): «Chalecos» RUTAS PANDORA - Raids (L-27 a M-28/07): «Chalecos» RUTAS ICARO - Preparación volantes (S-18/07 noche): «Chalecos» RUTAS ICARO - Volantes (x3 días) (D-19 a M-21/07): «Chalecos» RUTAS ICARO - Voluntariado Manuela (J-23/07): «Chalecos»
A86: Chalecos reflectantes | B86: Otros | C86: =SUM(D86:H86) | D86: 0 | E86: 0 | F86: 1 | G86: 0 | H86: 1 | I86: YA HAY (bases) - revisar | J86: EXPLORADORES - Servicio en el pueblo (J-23/07 mañana): «Chalecos reflectantes» RUTAS ICARO - Raids (L-27 a M-28/07): «Chalecos reflectantes»
A87: Chalecos reflectantes 1 por explorador y kraalete | B87: Otros | C87: =SUM(D87:H87) | D87: 0 | E87: 0 | F87: 1 | G87: 0 | H87: 0 | I87: YA HAY (bases) - revisar | J87: EXPLORADORES - Raids (L-27/07): «Chalecos reflectantes 1 por explorador y kraalete»
...

Sheet CASTORES
A1: FECHA / MOMENTO | B1: ACTIVIDAD | C1: MATERIAL (literal del docx)
A2: J-16/07 mañana | B2: Montaje de tiendas | C2: Tienda de campaña x2 Listones Tablas de madera Cuerda pita- 2 rollos Tijeras de punta redonda Martillo de goma Lona + segunda estructura de tienda (mochilero) Listones de los viejos para estructuras y mástil Bandera de castores Poleas para banderas Imperdibles x4
A3: J-16/07 tarde 1 | B3: Organizar mochilero | C3: Cajas grandes de cartón del chino por niño +3
A4: J-16/07 tarde 2 | B4: Normas de campamento + juegos | C4: Papel continuo 1m x 1m Rotuladores Celo gordo Tela pequeña o pañoleta (pañuelito) Balón
A5: V-17/07 mañana | B5: Construcciones zona común | C5: Listones Tablas de madera Cuerda pita- 2 rollos Tijeras de punta redonda Martillo de goma Listones de los viejos para estructuras y mástil Bandera de castores Poleas para banderas Imperdibles x4
A6: V-17/07 tarde | B6: Taller insignias | C6: Goma eva de colores Imperdibles Pompones pequeños Tijeras Pegamentos Silicona líquida para pegar los imperdibles
A7: V-17/07 tarde 2 | B7: T.E.G.A. (Torneo de Globos) | C7: Papel plastificado (lo lleva la comisión) Celo 150 globos 4 tobilleras de gimnasio o similares (ref Temu en el doc)
A8: V-17/07 noche | B8: Rastreo nocturno | C8: Cintas reflectantes amarillas Cintas reflectantes naranjas Paquete de sobres Leyendas de las constelaciones (comisión) - imprimir antes
A9: S-18/07 tarde 1 | B9: Gran Juego: El Taj perdido (con Lobatos) | C9: Témperas (colores a concretar) Taj Mahal impreso (se encarga la unidad) Pinceles Papel seda de colores Folios Balde Agua Goma eva de colores (vale con recortes) Pajitas Arco Papel continuo 1x1
A10: S-18/07 tarde 2 | B10: Hacer mochilas acampada volante | C10: Mochilas de cada castor Ropa Papel continuo Rotuladores
A11: S-18/07 noche | B11: Taller constelaciones | C11: Aislantes 3 mantas Puntero láser Altavoz (música relajante) Texto reflexión 'El Tren de los Sueños de Plata' (imprimir) Imagen de constelaciones (imprimir) Frontal o linterna del móvil
A12: D-19 a M-21/07 | B12: Acampada volante (x3 días) | C12: Lumi gas Comida del día (menú de volantes) Botiquín Chalecos y Walkie talkies Gorras y cantimploras Cazuela y cuchara de madera Mechero Crema solar Bolsas de basura Fairy Estropajo Títulos fotocopia Tarjetas sanitarias niños
... A36: 19-21/07 | B36: MENÚ VOLANTE (para 14: 12 castores + 2 GC) | C36: Manzanas 14 Filetes de lomo 70 Tranchetes 32 Paté 5 latas Noodles 10 paquetes Salchichas 8 paquetes Leche deshidratada para 8L Cola Cao a ojo Galletas 14 rulos Pasta carbonara 9 paquetes Nocilla 2 botes Sopa 5 sobres Salchichón 1 rulo Tang 3 sobres de cada sabor Frutos secos variados Leche condensada antigoteo 2 botes Bolsas zip 1 paquete Sal en papel albal Fairy Estropajo Pan 4 barras A mayores: bolsas de basura, papel albal, chalecos, papel higiénico, 1 cazuela grande o 2 pequeñas, cuchara de madera, 1 quemador y 1 bombona pequeña desechables, mechero, botiquín, walkie talkies, plato/poto/cubiertos GC

Sheet LOBATOS
A1: FECHA / MOMENTO | B1: ACTIVIDAD | C1: MATERIAL (literal del docx)
A2: J-16/07 mañana | B2: Montaje | C2: Tiendas Hierros Tablas Listones Piquetas Mazas
A3: J-16/07 tarde 1 | B3: Construcción de parcela | C3: Listones Elementos de la naturaleza Mazas Cuerda pita Clavos
A4: J-16/07 tarde 2 | B4: Juegos | C4: Conos chinos Balón goma espuma Pañoletas
A5: V-17/07 mañana | B5: Juegos India | C5: Pinturas cara pintacaras (de pincel, no de pinturilla) Fieltro marrón oscuro x4 láminas A3 (bandas de flecos indias) Telas de las bases Piedras (de la campa) Una cazuela Pelota de tenis Parchís y fichas x3 Incienso
A6: V-17/07 tarde 1 | B6: Territorios | C6: Cartulinas A4 Dos fotos (a mayores, no de los niños) Cuerda pita (1m) Papel albal Precinto
A7: V-17/07 tarde 2 | B7: De aventura en la India | C7: Pañoleta Aros Bancos Comba Conos chinos Pelota blanda
A8: V-17/07 noche | B8: Juegos nocturnos | C8: Frontales Silbatos Objetos varios que se cojan de material
A9: S-18/07 tarde 1 | B9: El Taj perdido (con Castores) | C9: Témperas Taj Mahal impreso (se encarga la unidad) Pinceles Papel seda de colores Folios Balde Agua Goma eva de colores (recortes) Pajitas Arco Papel continuo 1x1
A10: S-18/07 tarde 2 | B10: Preparación mochila | C10: Papel continuo Rotulador Bolsas de basura grande 1 x niño Bolsa de basura mediana 1 x niño
A11: D-19 a M-21/07 | B11: Ruta volante (x3 días) | C11: Mapas 312-I, 315-II, 315-IV, 316-III Lumi gas Comida del día (menú de volantes) Botiquín Chalecos y Walkie talkies Gorras y cantimploras Cazuela y cuchara de madera Mechero Crema solar Bolsas de basura Papel higiénico Fairy Estropajo Títulos fotocopia Tarjetas sanitarias niños
A12: D-19/07 tarde | B12: Taller de pulseras | C12: Hilo coreano de diferentes colores (3 m x niño) Celo Tijeras
... A42: D-26/07 tarde | B42: GRUPAL: Barracas - El Gran Bazar | C42: (De la descripción) Garbanzos dorados (rupias) Baraja de cartas Balde de agua Canicas Saco de seda 3 cilindros con dibujos (tragaperras) 100 boletos lotería Latas de coca-cola con piedras Placa de cartón + puntas (plinko) Dado gigante Pelotas de ping pong Vasija Vaso de chupito Monedas de céntimo Aro y cono

Sheet EXPLORADORES
A1: FECHA / MOMENTO | B1: ACTIVIDAD | C1: MATERIAL (literal del docx)
A2: J-16/07 mañana+tarde | B2: Construcciones rústicas | C2: 2 rollos de pita grandes 6 alcotanas Maderas varias para parcela y FELSA Clavos (indeterminados) 2 poleas para bandera Tiendas Piquetas Listón para mástil Listón para potero Listones para portada Estructura para mochilero con hierros y lonas Estructura para tendedero
A3: J-16/07 tarde | B3: Juegos (Tropiolimpiadas - cerbatanas) | C3: Tubos de PVC liso 16mm cortados a 50cm (1 por explorador) Lanzadoras tipo Nerf (unidad, solo monitores) Dardos de gomaespuma (unidad) Lija de grano fino Cinta aislante de colores 30 pinzas de 3 colores distintos (10 de cada)
A4: V-17/07 mañana | B4: Presentación profunda | C4: Tarjetas de personajes (unidad) Cofre cerrado con candado y varias llaves Folios y rotuladores 5 sobres Post-its (3 como mucho)
A5: V-17/07 tarde 1 | B5: Construcciones adicionales | C5: Sombrajo Clavos Cuerda gruesa (ni soga ni pita) Tablones de madera Tablita para columpio Tablas rotas Listones circulares
A6: V-17/07 tarde 2 | B6: Inauguración de la FELSA | C6: (Se encarga la unidad) Cuadrilátero acabado Corchera Nombres de los niños Rana de sorteo Chinchetas Caja con pañoletas de juego, cinturones, silbato, pañoleta de ganador Cancioneros
A7: V-17/07 noche | B7: Velada de código morse | C7: Silbato o linterna x3 Folios (unos 4) 2 rotuladores 5 objetos 'tesoro': 2 mazas, 2 telas/objetos amarillos, 2 pinceles, 2 botellines o latas
A8: S-18/07 tarde 1 | B8: Taller de hornillo | C8: Lata de aluminio 2 por niño Alcohol 96º Alambre Mechero
A9: S-18/07 tarde 2 | B9: Preparación de volantes | C9: Bolsas de basura (para guardar ropa) Botiquín con lo indispensable (kraalete) Comida volante
A10: S-18/07 noche | B10: Preparación de volantes (noche) | C10: Mapas Frontales Lumi Brújula
A11: D-19 a M-21/07 | B11: Volante (x3 días) | C11: Mapas Comida Menaje Botiquín unidad Chalecos Navaja Mochilas volante Brújulas Walkie-talkies
A12: D-19/07 tarde | B12: Taller de relajación | C12: Esterilla
... A35: Lluvia | B35: Guardián de las llaves / Pueblo duerme | C35: Manojo de llaves o cascabel Pañoleta para vendar ojos Periódico enrollado o churro de piscina Pinzas (cobras)

Sheet PIONEROS
A1: FECHA / MOMENTO | B1: ACTIVIDAD | C1: MATERIAL (literal del docx)
A2: J-16 y V-17/07 | B2: Construcciones | C2: 10m sombrajo 100m cuerda pita 5 listones (puerta + sombrajo) Alcotanas
A3: V-17/07 tarde | B3: Gymkhana deportes | C3: Bancos, mesa (circuito) Conos bajos de colores Cuerda gorda (sogatira) Palas de playa y pelota Palas de ping pong y pelotitas Red de volleyball Petanca Medallas de goma eva (las hace el kraalete)
A4: V-17/07 noche | B4: Taller de estrellas | C4: Cartulinas amarillas 2 A4 Precinto Bolígrafos/Rotus Tijeras Cuento/leyendas de estrellas Aislantes (los suyos)
A5: S-18/07 tarde 1 | B5: Actividad Clan Ícaro - Drogas | C5: Papel Boli Botellas de plástico Algodón Cigarrillos Mechero Balde Cartas
A6: S-18/07 tarde 2 | B6: Preparación volantes | C6: Comida volantes y menaje Botiquín pequeño Rafias
A7: S-18/07 noche | B7: Preparación volantes (noche) | C7: Mapas (poner números) Frontales Lumis
A8: D-19 a M-21/07 | B8: Volantes (x3 días) | C8: Mapa hoja 316 21-13 Quintanar de la Sierra Comida + menaje Botiquín unidad Chalecos Navaja Mochilas volante Reflexiones
A9: D-19/07 noche | B9: Juegos de cartas tradicionales | C9: Baraja española de cartas COMPLETA
A10: M-21/07 tarde | B10: Piscina pueblo Quintanar | C10: (Lo trae el niño) Toalla Bañador y chanclas Mochila pequeña
A11: L-20/07 noche | B11: Pulseras | C11: Gomitas de colores para pulseras Cordino y cuerda para pulseras y trenzas de pelo
A12: M-21/07 tarde 2 | B12: Relax | C12: Altavoz (kraalete) y móvil Cremita aftersun Aislantes (los nuestros)
... A36: Lluvia | B36: Pintar mandalas | C36: Mandalas (fotocopiar) Pinturas de palo Rotuladores de colores

Sheet RUTAS PANDORA
A1: FECHA / MOMENTO | B1: ACTIVIDAD | C1: MATERIAL (literal del docx)
A2: J-16/07 | B2: Actividad de adicciones con pipis | C2: Papel Boli Botella de plástico Algodón Cigarrillos Mechero Balde Cartas
A3: V-17/07 | B3: PPV | C3: Cuerda Post-its Bolígrafos Folios Permanentes Rotuladores
A4: S-18/07 | B4: Preparación acampada volante | C4: Mapas de la zona (pdte)
A5: D-19 a M-21/07 | B5: Acampada volante (x3 días) | C5: Camping gas Comida del día Cazuelas y cucharas de madera Chalecos Mapas de la zona 316I, 316III, 348I y 348III Botiquín Cerillas o mechero Limpieza (bolsas basura, fairy, estropajo) Títulos fotocopiados Tarjetas sanitarias
A6: Volante noche | B6: Línea de la vida | C6: Velas pequeñas (15) Cerillas/mecheros Aislantes Reflexiones
A7: X-22/07 | B7: Estiramientos post-volante | C7: Esterillas
A8: X-22/07 noche | B8: Juegos de mesa | C8: Juegos de mesa nuestros y de las bases
A9: J-23/07 | B9: Cocina con hándicaps (gyozas/empanadillas) | C9: Cinta aislante Pañoleta (vendar ojos) Cascos inalámbricos y un móvil (o tapones) Camping gas Bandejas Papel film Comida: masa de empanadillas 750g harina de trigo Sal 1L caldo de pollo 2 pechugas de pollo 4 huevos 4 dientes de ajo Salsa de soja Jengibre 1 cebolleta 2 puerros Salmón Carne picada de cerdo 250g Pimienta Aceite Agua
A10: J-23/07 noche | B10: Debates con roles | C10: Papel Boli
A11: V-24/07 | B11: Voluntariado Neila | C11: Falta confirmar si dejan todo o llevamos nosotros Coche/furgo para llegar
A12: V-24/07 noche | B12: PPV (velada) | C12: Velas altas Mantas Altavoz Mini tronquitos Permanentes finos negros Cajas pandora (ellas)
... A22: Reserva | B22: Carrera de orientación | C22: Mapa de la zona Brújulas Pinzas de orientación

Sheet RUTAS ICARO
A1: FECHA / MOMENTO | B1: ACTIVIDAD | C1: MATERIAL (literal del docx)
A2: J-16/07 | B2: Construcciones | C2: Tienda Cuerda pita Mástil Bandera rutas Imperdibles Cordino para bandera Portada: 6 listones Cartel rutas Hierros y listones para tendedero Listones sobrantes
A3: V-17/07 | B3: Taller Eva | C3: Folios Bolis
A4: V-17/07 | B4: Taller David | C4: Folios Bolígrafo Bingo (David)
A5: V-17/07 | B5: PPV (Vali) | C5: Cuadernos PPV (los suyos) Bolis Tarjetas mochila a color impresa (A5) Rotus de colores Papelitos dinámica
A6: V-17/07 noche | B6: Velada Vision Board | C6: Cartulina A3 grises claras Periódicos y revistas (un par de cada) Rotuladores de colores y permanentes Bolis
A7: S-18/07 | B7: Taller para Pioneros - Drogas | C7: Papel Boli Botellas de plástico Algodón Cigarrillos Mechero Balde Cartas
A8: S-18/07 | B8: Actividad moverse (Charlie) | C8: Pelotas Cuerda Papel Un boli
A9: S-18/07 noche | B9: Preparación volantes | C9: Mapas de la zona 316I, 316III, 348I y 348III Comida y menaje Botiquín unidad Chalecos
A10: D-19 a M-21/07 | B10: Volantes (x3 días) | C10: Mapas de la zona 316I, 316III, 348I y 348III Comida y menaje Botiquín unidad Chalecos Mochilas volante Cordino
A11: Volante noche | B11: Línea de la vida | C11: Velas pequeñas (15) Mechero/cerillas Aislantes Reflexiones y preguntas fotocopiadas (Vali)
A12: M-21/07 | B12: Talleres personales (Charlie) | C12: Rotus Navaja Una fruta para cada uno (naranja)
... A28: X-29/07 mañana | B28: OLIMPIADAS (grupal) | C28: Hierros de tiendas de 3-4 tamaños Bancos del comedor Balón Mantas Cuerda pita Martillo Clavos Potos/vasos Pelotas de pin-pon Dos pañoletas Vaso de plástico Velas Mechero Sacos para carrera de sacos

Sheet ALIMENTACIÓN
A1: -- INGREDIENTES DE TALLERES DE COCINA --
A2: UNIDAD | B2: FECHA / DÍA | C2: TALLER DE COCINA | D2: INGREDIENTES REQUERIDOS
A3: CASTORES | B3: D-19 a M-21/07 | C3: Acampada volante (x3 días) | D3: Comida del día (menú de volantes)
A4: CASTORES | B4: D-19 a M-21/07 | C4: Acampada volante (x3 días) | D4: Estropajo
A5: CASTORES | B5: M-21/07 tarde 2 | C5: Taller de tortitas (con Exploradores) | D5: Toppings: Nocilla x3, chocolate x3, mermelada x4 botes Medidas por niño: Harina 80-100g, Leche 100-120ml, 1/2 huevo, 1 cda azúcar, dado de mantequilla, pizca levadura en polvo, pizca de sal
A6: CASTORES | B6: M-21/07 tarde 2b | C6: Taller pulseras (lo dan Exploradores) | D6: Cordino (1.5 m por participante)
A7: CASTORES | B7: J-23/07 mañana | C7: Taller de cocina - Nariyal Ladoo | D7: Fruta en almíbar sobrante Compra (20 niños): Coco rallado 1kg Leche condensada 2 botes grandes (740g) Granadina 1 botella Mantequilla 1 bote Cardamomo 2 botes de semillas (o 1 en polvo)
A8: LOBATOS | B8: D-19 a M-21/07 | C8: Ruta volante (x3 días) | D8: Comida del día (menú de volantes)
A9: LOBATOS | B9: D-19 a M-21/07 | C9: Ruta volante (x3 días) | D9: Estropajo
A10: LOBATOS | B10: J-23/07 mañana | C10: Voluntariado conjunto Lobatos-Pioneros | D10: Comida
A11: LOBATOS | B11: J-23/07 día | C11: Piscina pueblo (con Pioneros) | D11: Comida al pueblo (bocadillo)
A12: LOBATOS | B12: V-24/07 tarde 1 | C12: Clan Ícaro: brújula casera y potabilizar | D12: Harina
A13: LOBATOS | B13: V-24/07 tarde 1 | C13: Clan Ícaro: brújula casera y potabilizar | D13: Sal
... A61: RUTAS ICARO | B61: L-27 a M-28/07 | C61: Raids | D61: Huevos cocidos
A64: -- MENÚ DE VOLANTES (Ingredientes Desglosados) --
A65: UNIDAD | B65: FECHA / DÍA | C65: ACTIVIDAD / ORIGEN | D65: INGREDIENTE / CANTIDAD
A66: CASTORES | B66: 19-21/07 | C66: MENÚ VOLANTE (para 14: 12 castores + 2 GC) | D66: Manzanas 14
A67: CASTORES | B67: 19-21/07 | C67: MENÚ VOLANTE (para 14: 12 castores + 2 GC) | D67: Filetes de lomo 70
A68: CASTORES | B68: 19-21/07 | C68: MENÚ VOLANTE (para 14: 12 castores + 2 GC) | D68: Tranchetes 32
A69: CASTORES | B69: 19-21/07 | C69: MENÚ VOLANTE (para 14: 12 castores + 2 GC) | D69: Paté 5 latas
A70: CASTORES | B70: 19-21/07 | C70: MENÚ VOLANTE (para 14: 12 castores + 2 GC) | D70: Noodles 10 paquetes
A71: CASTORES | B71: 19-21/07 | C71: MENÚ VOLANTE (para 14: 12 castores + 2 GC) | D71: Salchichas 8 paquetes
A72: CASTORES | B72: 19-21/07 | C72: MENÚ VOLANTE (para 14: 12 castores + 2 GC) | D72: Leche deshidratada para 8L
A73: CASTORES | B73: 19-21/07 | C73: MENÚ VOLANTE (para 14: 12 castores + 2 GC) | D73: Cola Cao a ojo
A74: CASTORES | B74: 19-21/07 | C74: MENÚ VOLANTE (para 14: 12 castores + 2 GC) | D74: Galletas 14 rulos
A75: CASTORES | B75: 19-21/07 | C75: MENÚ VOLANTE (para 14: 12 castores + 2 GC) | D75: Pasta carbonara 9 paquetes
A76: CASTORES | B76: 19-21/07 | C76: MENÚ VOLANTE (para 14: 12 castores + 2 GC) | D76: Nocilla 2 botes
... A87: CASTORES | B87: 19-21/07 | C87: MENÚ VOLANTE (para 14: 12 castores + 2 GC) | D87: A mayores: bolsas de basura, papel albal, chalecos, papel higiénico, 1 cazuela grande o 2 pequeñas, cuchara de madera, 1 quemador y 1 bombona pequeña desechables, mechero, botiquín, walkie talkies, plato/poto/cubiertos GC (limpieza/material - ver lista principal)

Sheet REPARTO CAJAS
A1: MATERIAL | B1: CAJA | C1: CANTIDAD REPARTIDA
